2020-06-16 14:44:00,466 INFO: Microblog startup [in /home/al/microblog/app/__init__.py:45]
2020-06-16 14:44:05,282 INFO: Microblog startup [in /home/al/microblog/app/__init__.py:45]
2020-06-16 15:53:46,909 INFO: Microblog startup [in /home/al/microblog/app/__init__.py:45]
2020-06-16 15:54:23,408 INFO: Microblog startup [in /home/al/microblog/app/__init__.py:45]
2020-06-16 15:59:54,180 INFO: Microblog startup [in /home/al/microblog/app/__init__.py:45]
2020-06-16 16:44:09,595 INFO: Microblog startup [in /home/al/microblog/app/__init__.py:45]
2020-06-16 17:17:45,995 INFO: Microblog startup [in /home/al/microblog/app/__init__.py:47]
2020-06-16 18:59:32,413 INFO: Microblog startup [in /home/al/microblog/app/__init__.py:49]
2020-06-16 18:59:42,980 INFO: Microblog startup [in /home/al/microblog/app/__init__.py:49]
2020-06-16 18:59:45,269 ERROR: Exception on /user/al [GET] [in /home/al/microblog/venv/lib/python3.6/site-packages/flask/app.py:1892]
Traceback (most recent call last):
  File "/home/al/microblog/venv/lib/python3.6/site-packages/flask/app.py", line 2447, in wsgi_app
    response = self.full_dispatch_request()
  File "/home/al/microblog/venv/lib/python3.6/site-packages/flask/app.py", line 1952, in full_dispatch_request
    rv = self.handle_user_exception(e)
  File "/home/al/microblog/venv/lib/python3.6/site-packages/flask/app.py", line 1821, in handle_user_exception
    reraise(exc_type, exc_value, tb)
  File "/home/al/microblog/venv/lib/python3.6/site-packages/flask/_compat.py", line 39, in reraise
    raise value
  File "/home/al/microblog/venv/lib/python3.6/site-packages/flask/app.py", line 1950, in full_dispatch_request
    rv = self.dispatch_request()
  File "/home/al/microblog/venv/lib/python3.6/site-packages/flask/app.py", line 1936, in dispatch_request
    return self.view_functions[rule.endpoint](**req.view_args)
  File "/home/al/microblog/venv/lib/python3.6/site-packages/flask_login/utils.py", line 272, in decorated_view
    return func(*args, **kwargs)
  File "/home/al/microblog/app/routes.py", line 87, in user
    next_url=next_url, prev_url=prev_url)
  File "/home/al/microblog/venv/lib/python3.6/site-packages/flask/templating.py", line 140, in render_template
    ctx.app,
  File "/home/al/microblog/venv/lib/python3.6/site-packages/flask/templating.py", line 120, in _render
    rv = template.render(context)
  File "/home/al/microblog/venv/lib/python3.6/site-packages/jinja2/environment.py", line 1090, in render
    self.environment.handle_exception()
  File "/home/al/microblog/venv/lib/python3.6/site-packages/jinja2/environment.py", line 832, in handle_exception
    reraise(*rewrite_traceback_stack(source=source))
  File "/home/al/microblog/venv/lib/python3.6/site-packages/jinja2/_compat.py", line 28, in reraise
    raise value.with_traceback(tb)
  File "/home/al/microblog/app/templates/user.html", line 1, in top-level template code
    {% extends "base.html" %}
  File "/home/al/microblog/venv/lib/python3.6/site-packages/jinja2/environment.py", line 832, in handle_exception
    reraise(*rewrite_traceback_stack(source=source))
  File "/home/al/microblog/venv/lib/python3.6/site-packages/jinja2/_compat.py", line 28, in reraise
    raise value.with_traceback(tb)
  File "/home/al/microblog/app/templates/base.html", line 56, in template
    {% block content %}
jinja2.exceptions.TemplateAssertionError: block 'content' defined twice
2020-06-16 19:02:18,270 INFO: Microblog startup [in /home/al/microblog/app/__init__.py:49]
2020-06-16 19:02:21,846 ERROR: Exception on /user/al [GET] [in /home/al/microblog/venv/lib/python3.6/site-packages/flask/app.py:1892]
Traceback (most recent call last):
  File "/home/al/microblog/venv/lib/python3.6/site-packages/flask/app.py", line 2447, in wsgi_app
    response = self.full_dispatch_request()
  File "/home/al/microblog/venv/lib/python3.6/site-packages/flask/app.py", line 1952, in full_dispatch_request
    rv = self.handle_user_exception(e)
  File "/home/al/microblog/venv/lib/python3.6/site-packages/flask/app.py", line 1821, in handle_user_exception
    reraise(exc_type, exc_value, tb)
  File "/home/al/microblog/venv/lib/python3.6/site-packages/flask/_compat.py", line 39, in reraise
    raise value
  File "/home/al/microblog/venv/lib/python3.6/site-packages/flask/app.py", line 1950, in full_dispatch_request
    rv = self.dispatch_request()
  File "/home/al/microblog/venv/lib/python3.6/site-packages/flask/app.py", line 1936, in dispatch_request
    return self.view_functions[rule.endpoint](**req.view_args)
  File "/home/al/microblog/venv/lib/python3.6/site-packages/flask_login/utils.py", line 272, in decorated_view
    return func(*args, **kwargs)
  File "/home/al/microblog/app/routes.py", line 87, in user
    next_url=next_url, prev_url=prev_url)
  File "/home/al/microblog/venv/lib/python3.6/site-packages/flask/templating.py", line 140, in render_template
    ctx.app,
  File "/home/al/microblog/venv/lib/python3.6/site-packages/flask/templating.py", line 120, in _render
    rv = template.render(context)
  File "/home/al/microblog/venv/lib/python3.6/site-packages/jinja2/environment.py", line 1090, in render
    self.environment.handle_exception()
  File "/home/al/microblog/venv/lib/python3.6/site-packages/jinja2/environment.py", line 832, in handle_exception
    reraise(*rewrite_traceback_stack(source=source))
  File "/home/al/microblog/venv/lib/python3.6/site-packages/jinja2/_compat.py", line 28, in reraise
    raise value.with_traceback(tb)
  File "/home/al/microblog/app/templates/user.html", line 1, in top-level template code
    {% extends "base.html" %}
  File "/home/al/microblog/app/templates/base.html", line 1, in top-level template code
    {% extends 'bootstrap/base.html' %}
  File "/home/al/microblog/venv/lib/python3.6/site-packages/flask_bootstrap/templates/bootstrap/base.html", line 1, in top-level template code
    {% block doc -%}
  File "/home/al/microblog/venv/lib/python3.6/site-packages/flask_bootstrap/templates/bootstrap/base.html", line 4, in block "doc"
    {%- block html %}
  File "/home/al/microblog/venv/lib/python3.6/site-packages/flask_bootstrap/templates/bootstrap/base.html", line 20, in block "html"
    {% block body -%}
  File "/home/al/microblog/venv/lib/python3.6/site-packages/flask_bootstrap/templates/bootstrap/base.html", line 23, in block "body"
    {% block content -%}
  File "/home/al/microblog/app/templates/user.html", line 24, in block "content"
    {% include '_post.html' %}
  File "/home/al/microblog/app/templates/_post.html", line 12, in top-level template code
    said {{ moment(post.timestamp).fromNow() }}:
jinja2.exceptions.UndefinedError: 'moment' is undefined
2020-06-16 19:02:43,635 INFO: Microblog startup [in /home/al/microblog/app/__init__.py:47]
2020-06-16 19:23:27,045 INFO: Microblog startup [in /home/al/microblog/app/__init__.py:49]
2020-06-16 22:56:50,320 INFO: Microblog startup [in /home/al/microblog/app/__init__.py:51]
2020-06-16 22:56:54,200 ERROR: Exception on /user/al [GET] [in /home/al/microblog/venv/lib/python3.6/site-packages/flask/app.py:1892]
Traceback (most recent call last):
  File "/home/al/microblog/venv/lib/python3.6/site-packages/flask/app.py", line 2447, in wsgi_app
    response = self.full_dispatch_request()
  File "/home/al/microblog/venv/lib/python3.6/site-packages/flask/app.py", line 1952, in full_dispatch_request
    rv = self.handle_user_exception(e)
  File "/home/al/microblog/venv/lib/python3.6/site-packages/flask/app.py", line 1821, in handle_user_exception
    reraise(exc_type, exc_value, tb)
  File "/home/al/microblog/venv/lib/python3.6/site-packages/flask/_compat.py", line 39, in reraise
    raise value
  File "/home/al/microblog/venv/lib/python3.6/site-packages/flask/app.py", line 1950, in full_dispatch_request
    rv = self.dispatch_request()
  File "/home/al/microblog/venv/lib/python3.6/site-packages/flask/app.py", line 1936, in dispatch_request
    return self.view_functions[rule.endpoint](**req.view_args)
  File "/home/al/microblog/venv/lib/python3.6/site-packages/flask_login/utils.py", line 272, in decorated_view
    return func(*args, **kwargs)
  File "/home/al/microblog/app/routes.py", line 141, in user
    next_url=next_url, prev_url=prev_url, form=form)
  File "/home/al/microblog/venv/lib/python3.6/site-packages/flask/templating.py", line 138, in render_template
    ctx.app.jinja_env.get_or_select_template(template_name_or_list),
  File "/home/al/microblog/venv/lib/python3.6/site-packages/jinja2/environment.py", line 930, in get_or_select_template
    return self.get_template(template_name_or_list, parent, globals)
  File "/home/al/microblog/venv/lib/python3.6/site-packages/jinja2/environment.py", line 883, in get_template
    return self._load_template(name, self.make_globals(globals))
  File "/home/al/microblog/venv/lib/python3.6/site-packages/jinja2/environment.py", line 857, in _load_template
    template = self.loader.load(self, name, globals)
  File "/home/al/microblog/venv/lib/python3.6/site-packages/jinja2/loaders.py", line 127, in load
    code = environment.compile(source, name, filename)
  File "/home/al/microblog/venv/lib/python3.6/site-packages/jinja2/environment.py", line 638, in compile
    self.handle_exception(source=source_hint)
  File "/home/al/microblog/venv/lib/python3.6/site-packages/jinja2/environment.py", line 832, in handle_exception
    reraise(*rewrite_traceback_stack(source=source))
  File "/home/al/microblog/venv/lib/python3.6/site-packages/jinja2/_compat.py", line 28, in reraise
    raise value.with_traceback(tb)
  File "/home/al/microblog/app/templates/user.html", line 11, in template
    <p>Last seen on: {{ moment(user.last_seen).calendar()</p>
jinja2.exceptions.TemplateSyntaxError: unexpected '/'
2020-06-17 00:57:11,681 INFO: Microblog startup [in /home/al/microblog/app/__init__.py:52]
2020-06-17 01:14:40,083 INFO: Microblog startup [in /home/al/microblog/app/__init__.py:52]
